{
 "cells": [
  {
   "cell_type": "code",
   "execution_count": 2,
   "metadata": {},
   "outputs": [],
   "source": [
    "# This is a test"
   ]
  },
  {
   "cell_type": "code",
   "execution_count": 1,
   "metadata": {},
   "outputs": [
    {
     "name": "stderr",
     "output_type": "stream",
     "text": [
      "/home/vscode/.local/lib/python3.10/site-packages/baybe/telemetry.py:222: UserWarning: WARNING: BayBE Telemetry endpoint https://public.telemetry.baybe.p.uptimize.merckgroup.com:4317 cannot be reached. Disabling telemetry. The exception encountered was: ConnectionError, HTTPConnectionPool(host='verkehrsnachrichten.merck.de', port=80): Max retries exceeded with url: / (Caused by NameResolutionError(\"<urllib3.connection.HTTPConnection object at 0x7f151b4947f0>: Failed to resolve 'verkehrsnachrichten.merck.de' ([Errno -2] Name or service not known)\"))\n",
      "  warnings.warn(\n",
      "/home/vscode/.local/lib/python3.10/site-packages/tqdm/auto.py:21: TqdmWarning: IProgress not found. Please update jupyter and ipywidgets. See https://ipywidgets.readthedocs.io/en/stable/user_install.html\n",
      "  from .autonotebook import tqdm as notebook_tqdm\n"
     ]
    }
   ],
   "source": [
    "import pandas as pd\n",
    "import numpy as np\n",
    "from baybe import Campaign"
   ]
  },
  {
   "cell_type": "code",
   "execution_count": null,
   "metadata": {},
   "outputs": [],
   "source": [
    "# This is another test"
   ]
  }
 ],
 "metadata": {
  "kernelspec": {
   "display_name": "Python 3",
   "language": "python",
   "name": "python3"
  },
  "language_info": {
   "codemirror_mode": {
    "name": "ipython",
    "version": 3
   },
   "file_extension": ".py",
   "mimetype": "text/x-python",
   "name": "python",
   "nbconvert_exporter": "python",
   "pygments_lexer": "ipython3",
   "version": "3.10.12"
  }
 },
 "nbformat": 4,
 "nbformat_minor": 2
}
